<robot name="mesh_viewer" tesseract:make_convex="true">
  
  <link name="world"/>
  <link name="mesh_gltf2_link">
    <visual>
      <geometry>
        <mesh filename="package://tesseract/support/meshes/tesseract_material_mesh.glb"/>
      </geometry>
    </visual>
  </link>

  <joint name="mesh_gltf2_joint" type="revolute">
    <parent link="world"/>
    <child link="mesh_gltf2_link"/>
    <axis xyz="0 1 0"/>
    <origin xyz="0 -1 0.25"/>
    <limit effort="0" lower="-2.0944" upper="2.0944" velocity="6.2832"/>
  </joint>

  <link name="mesh_dae_link">
    <visual>
      <geometry>
        <mesh filename="package://tesseract/support/meshes/tesseract_material_mesh.dae"/>
      </geometry>
    </visual>
  </link>

  <joint name="mesh_dae_joint" type="revolute">
    <parent link="world"/>
    <child link="mesh_dae_link"/>
    <axis xyz="0 1 0"/>
    <origin xyz="0 1 0.25"/>
    <limit effort="0" lower="-2.0944" upper="2.0944" velocity="6.2832"/>
  </joint>

</robot>